Workbook

Sheet PPMP
A1: PROJECT PROCUREMENT MANAGEMENT PLAN (PPMP) 2024
A2: For 1st Quarter of CY 2024
A3: END-USER/UNIT: OD-TIPS
A5: Charged to: Performance Evaluation of the Long and Short Staple Spun Natural Textile Fiber (NTF)-Blended Yarns for RA 9242-Compliance Corporate Dress Apparel (Government Uniform Project)
A6: Projects, Programs and Activities (PAPs)
A7: UACS CODE | B7: Stock No. | C7: GENERAL DESCRIPTION | D7: QUANTITY/ | E7: UNIT PRICE | F7: ESTIMATED BUDGET | G7: Mode of Procurement | H7: DELIVERY TERM | I7: SCHEDULE/MILESTONE OF ACTIVITIES
D8: SIZE | I8: Jan | J8: Feb | K8: Mar | L8: PR No. and Date | M8: RFQ No. and Date | N8: PhilGEPS Reference No. and Date | O8: PhilGEPS Closing Date | P8: AOC No. and Date | Q8: PO No. and Date | R8: Name of Payee | S8: BURS/ORS Amount | T8: Budget Utilization Rate | U8: Conforme of PO Date | V8: COA Received of PO Date | W8: NTP Date | X8: Contract Effectivity Date | Y8: End of Contract | Z8: Extended End of Contract | AA8: Delivery Date | AB8: IAR No. and Date | AC8: ICS/PAR No. and Date | AD8: RIS No. and Date | AE8: RSMI No. and Date | AF8: DV Release Date | AG8: DV Amount | AH8: Disbursement Rate | AI8: REMARKS | AJ8: REMARKS
A9: (1) | B9: (2) | C9: (3) | D9: (4) | E9: (5) | F9: (6) | G9: (7) | H9: (8) | I9: (9) | J9: (10) | K9: (11) | L9: (12) | M9: (13) | N9: (14) | O9: (15) | P9: (16) | Q9: (17) | R9: (18) | S9: (19) | T9: (20) | U9: (21) | V9: (22) | W9: (23) | X9: (24) | Y9: (25) | Z9: (26) | AA9: (27) | AB9: (28) | AC9: (29) | AD9: (30) | AE9: (31) | AF9: (32) | AG9: (33) | AH9: (34) | AI9: (35) | AJ9: (35)
A10: 50299040 00 | C10: Transporation and Delivery Expenses
C11: Courier Fee | D11: 1 lot | E11: 215 | F11: 215 | G11: Petty Cash Fund | H11: per schedule | I11: 1
A12: 50299030 00 | C12: Representation Expenses
C13: Meals for Handloom Weaving Technical Committee Meeting | D13: 40 pax | E13: 750 | F13: =40*750 -> 30000 | G13: Shopping | H13: per schedule | I13: 40
C14: Meals for National Footwear Technical Working Group Meeting | D14: 50 pax | E14: 1000 | F14: =50*1000 -> 50000 | G14: Shopping | H14: per schedule | I14: 50
C15: Meals for Innovation Dialogue: Textile Producers | D15: 40 pax | E15: 750 | F15: =40*750 -> 30000 | G15: Shopping | H15: per schedule | I15: 40
C16: Meals Philippine Tropical Fabrics Technical Committee Meeting | D16: 30 pax | E16: 750 | F16: =30*750 -> 22500 | G16: Shopping | H16: per schedule | I16: 30
C17: Meals Inaugaration of the Meltblown Nonwoven Line, MOA Signing Ceremony - Spunlaid Nonwovens | D17: 30 pax | E17: 750 | F17: =30*750 -> 22500 | G17: Shopping | H17: per schedule | I17: 30
A18: 50203080 00 | C18: Medical, Dental Laboratory Supplies Expenses
B19: MDL-276 | C19: Hydrogen Peroxide, Technical Grade 25 L/cby | D19: 9 cby | E19: 8000 | F19: =9*E19 -> 72000 | G19: Negotiated Procurement-Small Value Procurement | H19: 60-90 working days | I19: 9
B20: MDL-041 | C20: Sodium Hydroxide, Liquid 48% 30 kg/cby | D20: 130 cby | E20: 3000 | F20: =E20*130 -> 390000 | G20: Negotiated Procurement-Small Value Procurement | H20: 60-90 working days | I20: 130
B21: MDL-077 | C21: Sodium Metabisulfite, Technical Grade | D21: 180 kg | E21: 350 | F21: =180*350 -> 63000 | G21: Negotiated Procurement-Small Value Procurement | H21: 60-90 working days | I21: 180
B22: OSMI-094 | C22: Anionic Detergent | D22: 50 gal | E22: 700 | F22: 396000 | G22: Negotiated Procurement-Small Value Procurement | H22: 60-90 working days | I22: 50
B23: MDL-004 | C23: Acetic Acid, Technical Grade 20 kg/cby | D23: 38 cby | E23: 9500 | I23: 38
A24: 50203990 00 | C24: Other Supplies Expenses
C25: "PAPER CONE 4°20’ Specifications: TOP ID: 27 mm ± 1.0 mm BOTTOM ID: 59 mm ± 1.0 mm LENGTH: 170 mm ± 1.0 mm THICKNESS: 2 mm WEIGHT: 40 g ± 2g" | D25: 5000 pcs | E25: 55 | F25: =5000*55 -> 275000 | G25: Negotiated Procurement-Small Value Procurement | H25: 60-90 working days | I25: 55
C26: DECORTICATED PINEAPPLE LEAF FIBERS Hawaiian or Formosa Variety Note: Including VAT and Delivery to ICYT Bldg., DOST-PTRI Bicutan, Taguig City | D26: 1500 kg | E26: 600 | F26: =1500*600 -> 900000 | G26: Negotiated Procurement-Small Value Procurement | H26: 60-90 working days | I26: 1500
C27: GINNED COTTON FIBER Note: Including VAT and Delivery to ICYT Bldg., DOST-PTRI Bicutan, Taguig City | D27: 1500 kg | E27: 140 | F27: =1500*140 -> 210000 | G27: Negotiated Procurement-Small Value Procurement | H27: 60-90 working days | I27: 1500
C28: Pineapple-based powerloom woven fabric - at least 5% pineapple fiber content - Assorted Colors - Fabric width: at least 55 inches - 11 rolls at 100 yards per roll | D28: 1100 yards | E28: 150 | F28: =1100*150 -> 165000 | G28: Negotiated Procurement-Small Value Procurement / Direct Contracting (if with MOA) | H28: 60-90 working days | I28: 1100
C29: Pineapple-based attire -Button down woven shirt with cotton and pineaapple leaf fiber | D29: 1 pc | E29: 6000 | F29: 6000 | G29: Direct Contracting | H29: 60-90 working days | I29: 6000
A30: 50203090 00 | C30: Fuel, Oil and Lubricants Expenses
C31: Diesel, 210 L/drum | D31: 30 drums | E31: 14000 | F31: =30*14000 -> 420000 | G31: Small Value Procurement | H31: 15 days | I31: 30
A32: 50211990 00 | C32: Other Professional Services
C33: ENZYME FINISHING and DYEING of Powerloom woven fabrics Weight: 40.7kgs Warp: 100% Polyester Warp: 70% cotton/ 30% Pineapple Leaf Fiber Shade: White, Beige, Yellow | D33: 1 lot | E33: 30000 | F33: 30000 | G33: Negotiated Procurement-Small Value Procurement / Direct Contracting (if with MOA) | H33: 60-90 working days | I33: 1
C34: Design and Prototype Development -12 looks, 20-30 pcs, ready-to-wear apparel made of bamboo and pineapple-based fabrics | D34: 1 lot | E34: 325000 | F34: =250000+75000 -> 325000 | G34: Negotiated Procurement-Small Value Procurement / Direct Contracting (if with MOA) | H34: 60-90 working days | I34: 1
C35: Professional Services for DOST-PTRI Ambassadors | D35: 1 lot | E35: 80000 | F35: 80000 | G35: Negotiated Procurement-Scientific, Artistic Works | H35: 60-90 working days | I35: 1
A36: TOTAL APPROVED BUDGET: | F36: =SUM(F11:F35) -> 3487215
A37: NOTE: Technical Specifications for each Item/Project being proposed shall be submitted as part of the PPMP
A39: Prepared by: | D39: Reviewed by: | G39: Certified Funds Available: | J39: Approved by:
A42: EVANGELINE FLOR P. MANALANG | D42: MARILOU G. AGUSTIN | G42: MERLITA R. ODI | J42: JULIUS L. LEAÑO JR., Ph.D.
A43: Project Leader | D43: Head, FAD-PPGSS | G43: Head, FAD-BTS | J43: Director IV
A45: Date: ______________________ | D45: Date: _____________ | G45: Date: _____________ | J45: Date: _____________

Sheet Copy of PPMP
A1: PROJECT PROCUREMENT MANAGEMENT PLAN (PPMP) 2024
A2: For 1st Quarter of CY 2024
A4: END-USER/UNIT: OD-TIPS
A6: Charged to: Performance Evaluation of the Long and Short Staple Spun Natural Textile Fiber (NTF)-Blended Yarns for RA 9242-Compliance Corporate Dress Apparel (Government Uniform Project)
A7: Projects, Programs and Activities (PAPs)
A8: CODE | B8: GENERAL DESCRIPTION | C8: QUANTITY/ | D8: UNIT PRICE | E8: ESTIMATED BUDGET | F8: Mode of Procurement | G8: DELIVERY TERM | H8: SCHEDULE/MILESTONE OF ACTIVITIES
C9: SIZE | H9: Jan | I9: Feb | J9: Mar | K9: PR No. | L9: RFQ No. | M9: PhilGEPS Reference No. | N9: AOC No. | O9: PO No. | P9: COA Received Date | Q9: NTP No. | R9: IAR No. | S9: ICS/PAR No. | T9: RIS/RSMI No. | U9: REMARKS | V9: REMARKS
B10: OFFICE SUPPLIES
B17: Transporation and Delivery Expenses
B18: Courier Fee | C18: 1 lot | D18: 215 | E18: 215 | F18: Shopping | G18: CA | H18: 1
B20: Representation
B21: Meals for Handloom Weaving Technical Committee Meeting | C21: 40 pax | D21: 750 | E21: =40*750 -> 30000 | F21: Shopping | G21: 15 days | H21: 40
B22: Meals for National Footwear Technical Working Group Meeting | C22: 50 pax | D22: 1000 | E22: =50*1000 -> 50000 | F22: Shopping | G22: 15 days | H22: 50
B23: Meals for Innovation Dialogue: Textile Producers | C23: 40 pax | D23: 750 | E23: =40*750 -> 30000 | F23: Shopping | G23: 15 days | H23: 40
B24: Meals Philippine Tropical Fabrics Technical Committee Meeting | C24: 30 pax | D24: 750 | E24: =30*750 -> 22500 | F24: Shopping | G24: 15 days | H24: 30
B25: Meals Inaugaration of the Meltblown Nonwoven Line, MOA Signing Ceremony - Spunlaid Nonwovens | C25: 30 pax | D25: 750 | E25: =30*750 -> 22500 | F25: Shopping | G25: 15 days | H25: 30
B27: Laboratory Supplies
B28: Hydrogen Peroxide, Technical Grade 25 L/cby | C28: 9 cby | D28: 8000 | E28: =9*D28 -> 72000 | F28: Shopping | G28: 15 days | H28: 9
B29: Sodium Hydroxide, Liquid 48% 30 kg/cby | C29: 130 cby | D29: 3000 | E29: =D29*130 -> 390000 | F29: Small Value Procurement | G29: 15 days | H29: 130
B30: Sodium Metabisulfite, Technical Grade | C30: 180 kg | D30: 350 | E30: =180*350 -> 63000 | F30: Small Value Procurement | G30: 15 days | H30: 180
B31: Anionic Detergent | C31: 50 gal | D31: 700 | E31: =50*700 -> 35000 | F31: Shopping | G31: 15 days | H31: 50
B32: Acetic Acid, Technical Grade 20 kg/cby | C32: 38 cby | D32: 9500 | E32: =38*9500 -> 361000 | F32: Small Value Procurement | G32: 15 days | H32: 38
B33: Other Supplies
B34: "PAPER CONE 4°20’ Specifications: TOP ID: 27 mm ± 1.0 mm BOTTOM ID: 59 mm ± 1.0 mm LENGTH: 170 mm ± 1.0 mm THICKNESS: 2 mm WEIGHT: 40 g ± 2g" | C34: 5000 pcs | D34: 55 | E34: =5000*55 -> 275000 | F34: Small Value Procurement | G34: 15 days | H34: 55
B35: DECORTICATED PINEAPPLE LEAF FIBERS Hawaiian or Formosa Variety Note: Including VAT and Delivery to ICYT Bldg., DOST-PTRI Bicutan, Taguig City | C35: 1500 kg | D35: 600 | E35: =1500*600 -> 900000 | F35: Small Value Procurement | G35: 30 days | H35: 1500
B36: GINNED COTTON FIBER Note: Including VAT and Delivery to ICYT Bldg., DOST-PTRI Bicutan, Taguig City | C36: 1500 kg | D36: 140 | E36: =1500*140 -> 210000 | F36: Small Value Procurement | G36: 30 days | H36: 1500
B38: Pineapple-based powerloom woven fabric | C38: 1100 yards | D38: 150 | E38: =1100*150 -> 165000 | F38: Direct Contracting | G38: 15 days | H38: 1100
B39: - at least 5% pineapple fiber content
B40: - Assorted Colors
B41: - Fabric width: at least 55 inches
B42: - 11 rolls at 100 yards per roll
B44: Pineapple-based attire | C44: 1 pc | D44: 6000 | E44: 6000 | F44: Direct Contracting | G44: 15 days | H44: 6000
B45: Button down woven shirt with cotton and pineaapple leaf fiber
B47: FUELS, OILS, LUBRICANTS
B48: Diesel, 210 L/drum | C48: 30 drums | D48: 14000 | E48: =30*14000 -> 420000 | F48: Small Value Procurement | G48: 15 days | H48: 30
B50: Other Professional Services
B51: ENZYME FINISHING and DYEING of Powerloom woven fabrics | C51: 1 lot | D51: 30000 | E51: 30000 | F51: Direct Contracting | G51: 15 days | H51: 1
B52: Weight: 40.7kgs
B53: Warp: 100% Polyester
B54: Warp: 70% cotton/ 30% Pineapple Leaf Fiber
...

Sheet PPGSS Tracking slip
A1: Department of Science and Technology
A2: PHILIPPINE TEXTILE RESEARCH INSTITUTE | E2: Documents
A3: FINANCE AND ADMINISTRATIVE DIVISION | E3: TRACKING
A4: Property, Procurement and General Services Section | E4: SLIP
A5: PARTICULARS | B5: Number | C5: Date (d/m/y) | D5: Amount | E5: TYPE OF DOCUMENT
A6: PR | F6: LETTER / NOTES / MEMO / ORDERS
A7: RFQ | F7: PR / ICT Clearance / RFQ / APR-PS
A8: PhilGEPS | F8: AOC / RESOLUTION / PHILGEPS
A9: AOC | F9: PO / NOTICE to PROCEED
A10: RESOLUTION | F10: NOTICE OF AWARD / LC / CONTRACTS
A11: PO / APR | F11: Request for Pre-Repair & Post Insp.
A12: ORS / BURS | F12: IAR / ICS / PAR / WMR / RIS / RSMI
A13: IAR | F13: DV / CHECK
A14: PAYEE | F14: OTHERS
A15: DATE (day/month/year) | C15: DIVISION / SECTION | E15: INITIAL | F15: ACTION TAKEN / REMARKS
A16: RECEIVED | B16: RELEASED | C16: FROM | D16: TO
A29: PLEASE DO NOT DETACH
A32: Department of Science and Technology
A33: PHILIPPINE TEXTILE RESEARCH INSTITUTE | E33: Documents
A34: FINANCE AND ADMINISTRATIVE DIVISION | E34: TRACKING
A35: Property, Procurement and General Services Section | E35: SLIP
A36: PARTICULARS | B36: Number | C36: Date (d/m/y) | D36: Amount | E36: TYPE OF DOCUMENT
A37: PR | F37: LETTER / NOTES / MEMO / ORDERS
A38: RFQ | F38: PR / ICT Clearance / RFQ / APR-PS
A39: PhilGEPS | F39: AOC / RESOLUTION / PHILGEPS
A40: AOC | F40: PO / NOTICE to PROCEED
A41: RESOLUTION | F41: NOTICE OF AWARD / LC / CONTRACTS
A42: PO / APR | F42: Request for Pre-Repair & Post Insp.
A43: ORS / BURS | F43: IAR / ICS / PAR / WMR / RIS / RSMI
A44: IAR | F44: DV / CHECK
A45: PAYEE | F45: OTHERS
A46: DATE (day/month/year) | C46: DIVISION / SECTION | E46: INITIAL | F46: ACTION TAKEN / REMARKS
A47: RECEIVED | B47: RELEASED | C47: FROM | D47: TO
A60: PLEASE DO NOT DETACH

Sheet Summary
A1: No. | B1: PR Date | C1: Current Status | D1: PR no. | E1: Item Descriptions | F1: Qty | G1: Unit | H1: Unit Cost (PHP) | I1: Total ABC | J1: Status
A2: 1 | B2: 45299 | C2: for PR number (received by Sir Boysen) -3:10 PM -Jan.8,2024 | E2: PAPER CONE 4°20’ Specifications: TOP ID: 27 mm ± 1.0 mm BOTTOM ID: 59 mm ± 1.0 mm LENGTH: 170 mm ± 1.0 mm THICKNESS: 2 mm WEIGHT: 40 g ± 2g | F2: 5000 | G2: pcs | H2: 55 | I2: =F2*H2 -> 275000
A4: 2 | B4: 45299 | C4: for PR number (received by Sir Boysen) -3:10 PM -Jan.8,2024 | E4: DECORTICATED PINEAPPLE LEAF FIBERS Hawaiian or Formosa Variety Note: Including VAT and Delivery to ICYT Bldg., DOST-PTRI Bicutan, Taguig City | F4: 1500 | G4: kg | H4: 600 | I4: =F4*H4 -> 900000
A6: 3 | B6: 45299 | C6: for PR number (received by Sir Boysen) -3:10 PM -Jan.8,2024 | E6: GINNED COTTON FIBER Note: Including VAT and Delivery to ICYT Bldg., DOST-PTRI Bicutan, Taguig City | F6: 1500 | G6: kg | H6: 140 | I6: =F6*H6 -> 210000
A8: 4 | B8: 45299 | C8: for PR number (received by Sir Boysen) -3:10 PM -Jan.8,2024 | E8: CHEMICALS
E9: Hydrogen Peroxide, Technical Grade 25 L/cby | F9: 9 | G9: cby | H9: 8000 | I9: =F9*H9 -> 72000
E10: Sodium Hydroxide, Liquid 48% 30 kg/cby | F10: 130 | G10: cby | H10: 3000 | I10: =F10*H10 -> 390000
E11: Sodium Metabisulfite, Technical Grade | F11: 180 | G11: kg | H11: 350 | I11: =F11*H11 -> 63000
E12: Anionic Detergent | F12: 50 | G12: gal | H12: 700 | I12: =F12*H12 -> 35000
E13: Acetic Acid, Technical Grade 20 kg/cby | F13: 38 | G13: cby | H13: 9500 | I13: =F13*H13 -> 361000
A15: 5 | B15: 45299 | C15: for PR number (received by Sir Boysen) -3:10 PM -Jan.8,2024 | E15: ENZYME FINISHING and DYEING of Powerloom woven fabrics | F15: 1 | G15: lot | H15: 30000 | I15: 30000
E16: Weight: 40.7kgs
E17: Warp: 100% Polyester
E18: Warp: 70% cotton/ 30% Pineapple Leaf Fiber
E19: Shade: White, Beige, Yellow
A21: 6 | E21: DIESEL FUEL | F21: 30 | G21: drums | H21: 14000 | I21: =F21*H21 -> 420000
E22: 210 liters / drum

Sheet PR TEMPLATE
A1: FAD-PPGSS Form No. 15
A2: Rev. 1/15-05-17
A3: PURCHASE REQUEST
A4: Philippine Textile Research Institute
A5: Division | B5: OFFICE OF THE DIRECTOR | D5: P.R. No. | F5: dtd.
A6: Section | B6: Technology Transfer, Information & Promotion Staff | D6: SAI No. | F6: dtd.
A8: Stock No. | B8: Unit | C8: Item Description | D8: Qty. | E8: Unit Cost | F8: Total Cost
A9: 1 | F9: =E9*D9 -> 0
C12: -x-x-x-x-x-x-x-x-nothing follows-x-x-x-x-x-x-x-
C13: Charge to: GAA-TIPS: 2024 Uniform | F13: =sum(F9) -> 0
A14: Purpose: To be used for the project
C15: Requested by : | D15: Approved by :
A17: Signature
A18: Printed Name | C18: EVANGELINE FLOR P. MANALANG | D18: JULIUS L. LEAÑO JR.
A19: Designation | C19: Project Leader/ Head, OD-TIPS | D19: Director IV
A20: Date | C20: 45306
A23: FAD-PPGSS Form No. 15
A24: Rev. 1/15-05-17
A25: PURCHASE REQUEST
A26: Philippine Textile Research Institute
A27: Division | B27: OFFICE OF THE DIRECTOR | D27: P.R. No. | F27: dtd.
A28: Section | B28: Technology Transfer, Information & Promotion Staff | D28: SAI No. | F28: dtd.
A30: Stock No. | B30: Unit | C30: Item Description | D30: Qty. | E30: Unit Cost | F30: Total Cost
A31: 1 | B31: =B9 | C31: =C9 | D31: =D9 | E31: =E9 | F31: =E31*D31 -> 0
C34: -x-x-x-x-x-x-x-x-nothing follows-x-x-x-x-x-x-x-
C35: Charge to: GAA-TIPS: 2024 Uniform | F35: =sum(F31) -> 0
A36: Purpose: To be used for the project
C37: Requested by : | D37: Approved by :
A39: Signature
A40: Printed Name | C40: EVANGELINE FLOR P. MANALANG | D40: JULIUS L. LEAÑO JR.
A41: Designation | C41: Project Leader/ Head, OD-TIPS | D41: Director IV
A42: Date | C42: =C20 -> 45306

Sheet Fabric Enzyme finishing and dye
A1: FAD-PPGSS Form No. 15
A2: Rev. 1/15-05-17
A3: PURCHASE REQUEST
A4: Philippine Textile Research Institute
A5: Division | B5: OFFICE OF THE DIRECTOR | D5: P.R. No. | F5: dtd.
A6: Section | B6: Technology Transfer, Information & Promotion Staff | D6: SAI No. | F6: dtd.
A8: Stock No. | B8: Unit | C8: Item Description | D8: Qty. | E8: Unit Cost | F8: Total Cost
B9: lot | C9: Enzyme finishing and dyeing of powerloom fabrics | D9: 1 | E9: 30000 | G9: =E9 -> 30000
C10: Weight: 40.7kgs
C11: Warp: 100% Polyester
C12: Warp: 70% cotton/ 30% Pineapple Leaf Fiber
C13: Shade: White, Beige, Yellow
C17: -x-x-x-x-x-x-x-x-nothing follows-x-x-x-x-x-x-x-
C19: Charge to: GAA-TIPS: 2024 Uniform | G19: =sum(G9:G16) -> 30000
A20: Purpose: To be used for the project
C21: Requested by : | D21: Approved by :
A23: Signature
A24: Printed Name | C24: EVANGELINE FLOR P. MANALANG | D24: JULIUS L. LEAÑO JR.
A25: Designation | C25: Project Leader/ Head, OD-TIPS | D25: Director IV
A26: Date | C26: 45299
A29: FAD-PPGSS Form No. 15
A30: Rev. 1/15-05-17
A31: PURCHASE REQUEST
A32: Philippine Textile Research Institute
A33: Division | B33: OFFICE OF THE DIRECTOR | D33: P.R. No. | F33: dtd.
A34: Section | B34: Technology Transfer, Information & Promotion Staff | D34: SAI No. | F34: dtd.
A36: Stock No. | B36: Unit | C36: Item Description | D36: Qty. | E36: Unit Cost | F36: Total Cost
B37: lot | C37: Enzyme finishing and dyeing of powerloom fabrics | D37: 1 | E37: 30000 | G37: =E37 -> 30000
C38: Weight: 40.7kgs
C39: Warp: 100% Polyester
C40: Warp: 70% cotton/ 30% Pineapple Leaf Fiber
C41: Shade: White, Beige, Yellow
C45: -x-x-x-x-x-x-x-x-nothing follows-x-x-x-x-x-x-x-
C47: Charge to: GAA-TIPS: 2024 Uniform | G47: =sum(G37:G44) -> 30000
A48: Purpose: To be used for the project
C49: Requested by : | D49: Approved by :
A51: Signature
A52: Printed Name | C52: EVANGELINE FLOR P. MANALANG | D52: JULIUS L. LEAÑO JR.
A53: Designation | C53: Project Leader/ Head, OD-TIPS | D53: Director IV
A54: Date | C54: 45299

Sheet Paper cone
A1: FAD-PPGSS Form No. 15
A2: Rev. 1/15-05-17
A3: PURCHASE REQUEST
A4: Philippine Textile Research Institute
A5: Division | B5: OFFICE OF THE DIRECTOR | D5: P.R. No. | F5: dtd.
A6: Section | B6: Technology Transfer, Information & Promotion Staff | D6: SAI No. | F6: dtd.
A8: Stock No. | B8: Unit | C8: Item Description | D8: Qty. | E8: Unit Cost | F8: Total Cost
B9: pcs | C9: PAPER CONE 4°20’ Specifications: TOP ID: 27 mm ± 1.0 mm BOTTOM ID: 59 mm ± 1.0 mm LENGTH: 170 mm ± 1.0 mm THICKNESS: 2 mm WEIGHT: 40 g ± 2g | D9: 5000 | E9: 55 | F9: =E9*D9 -> 275000
C14: -x-x-x-x-x-x-x-x-nothing follows-x-x-x-x-x-x-x-
C16: Charge to: GAA-TIPS: 2024 Uniform | F16: =sum(F9) -> 275000
A17: Purpose: To be used for the project
C18: Requested by : | D18: Approved by :
A20: Signature
A21: Printed Name | C21: EVANGELINE FLOR P. MANALANG | D21: JULIUS L. LEAÑO JR.
A22: Designation | C22: Project Leader/ Head, OD-TIPS | D22: Director IV
A23: Date | C23: 45299
A25: FAD-PPGSS Form No. 15
A26: Rev. 1/15-05-17
A29: PURCHASE REQUEST
A30: Philippine Textile Research Institute
A31: Division | B31: OFFICE OF THE DIRECTOR | D31: P.R. No. | F31: dtd.
A32: Section | B32: Technology Transfer, Information & Promotion Staff | D32: SAI No. | F32: dtd.
A34: Stock No. | B34: Unit | C34: Item Description | D34: Qty. | E34: Unit Cost | F34: Total Cost
B35: pcs | C35: PAPER CONE 4°20’ Specifications: TOP ID: 27 mm ± 1.0 mm BOTTOM ID: 59 mm ± 1.0 mm LENGTH: 170 mm ± 1.0 mm THICKNESS: 2 mm WEIGHT: 40 g ± 2g | D35: 5000 | E35: 55 | F35: =E35*D35 -> 275000
C40: -x-x-x-x-x-x-x-x-nothing follows-x-x-x-x-x-x-x-
C42: Charge to: GAA-TIPS: 2024 Uniform | F42: =F16 -> 275000
A43: Purpose: To be used for the project
C44: Requested by : | D44: Approved by :
A46: Signature
A47: Printed Name | C47: EVANGELINE FLOR P. MANALANG | D47: JULIUS L. LEAÑO JR.
A48: Designation | C48: Project Leader/ Head, OD-TIPS | D48: Director IV
A49: Date | C49: 45299

Sheet DECORTICATED PINEAPPLE LEAF FIB
A1: FAD-PPGSS Form No. 15
A2: Rev. 1/15-05-17
A3: PURCHASE REQUEST
A4: Philippine Textile Research Institute
A5: Division | B5: OFFICE OF THE DIRECTOR | D5: P.R. No. | F5: dtd.
A6: Section | B6: Technology Transfer, Information & Promotion Staff | D6: SAI No. | F6: dtd.
A8: Stock No. | B8: Unit | C8: Item Description | D8: Qty. | E8: Unit Cost | F8: Total Cost
B9: kg | C9: DECORTICATED PINEAPPLE LEAF FIBERS Hawaiian or Formosa Variety Note: Including VAT and Delivery to ICYT Bldg., DOST-PTRI Bicutan, Taguig City | D9: 1500 | E9: 600 | F9: =E9*D9 -> 900000
C12: -x-x-x-x-x-x-x-x-nothing follows-x-x-x-x-x-x-x-
C14: Charge to: GAA-TIPS: 2024 Uniform | F14: =sum(F9) -> 900000
A15: Purpose: To be used for the project
C16: Requested by : | D16: Approved by :
A18: Signature
A19: Printed Name | C19: EVANGELINE FLOR P. MANALANG | D19: JULIUS L. LEAÑO JR.
A20: Designation | C20: Project Leader/ Head, OD-TIPS | D20: Director IV
A21: Date | C21: 45299
A25: FAD-PPGSS Form No. 15
A26: Rev. 1/15-05-17
A27: PURCHASE REQUEST
A28: Philippine Textile Research Institute
A29: Division | B29: OFFICE OF THE DIRECTOR | D29: P.R. No. | F29: dtd.
A30: Section | B30: Technology Transfer, Information & Promotion Staff | D30: SAI No. | F30: dtd.
A32: Stock No. | B32: Unit | C32: Item Description | D32: Qty. | E32: Unit Cost | F32: Total Cost
B33: =B9 -> kg | C33: DECORTICATED PINEAPPLE LEAF FIBERS Hawaiian or Formosa Variety Note: Including VAT and Delivery to ICYT Bldg., DOST-PTRI Bicutan, Taguig City" | D33: =D9 -> 1500 | E33: =E9 -> 600 | F33: =F9 -> 900000
C36: -x-x-x-x-x-x-x-x-nothing follows-x-x-x-x-x-x-x-
C38: Charge to: GAA-TIPS: 2024 Uniform | F38: =F14 -> 900000
A39: Purpose: To be used for the project
C40: Requested by : | D40: Approved by :
A42: Signature
A43: Printed Name | C43: EVANGELINE FLOR P. MANALANG | D43: JULIUS L. LEAÑO JR.
A44: Designation | C44: Project Leader/ Head, OD-TIPS | D44: Director IV
A45: Date | C45: 45299

Sheet GINNED COTTON FIBER      
A1: FAD-PPGSS Form No. 15
A2: Rev. 1/15-05-17
A3: PURCHASE REQUEST
A4: Philippine Textile Research Institute
A5: Division | B5: OFFICE OF THE DIRECTOR | D5: P.R. No. | F5: dtd.
A6: Section | B6: Technology Transfer, Information & Promotion Staff | D6: SAI No. | F6: dtd.
A8: Stock No. | B8: Unit | C8: Item Description | D8: Qty. | E8: Unit Cost | F8: Total Cost
B9: kg | C9: GINNED COTTON FIBER Note: Including VAT and Delivery to ICYT Bldg., DOST-PTRI Bicutan, Taguig City | D9: 1500 | E9: 140 | F9: =E9*D9 -> 210000
C12: -x-x-x-x-x-x-x-x-nothing follows-x-x-x-x-x-x-x-
C14: Charge to: GAA-TIPS: 2024 Uniform | F14: =sum(F9) -> 210000
A15: Purpose: To be used for the project
C16: Requested by : | D16: Approved by :
A18: Signature
A19: Printed Name | C19: EVANGELINE FLOR P. MANALANG | D19: JULIUS L. LEAÑO JR.
A20: Designation | C20: Project Leader/ Head, OD-TIPS | D20: Director IV
A21: Date | C21: 45299
A24: FAD-PPGSS Form No. 15
A25: Rev. 1/15-05-17
A26: PURCHASE REQUEST
A27: Philippine Textile Research Institute
A28: Division | B28: OFFICE OF THE DIRECTOR | D28: P.R. No. | F28: dtd.
A29: Section | B29: Technology Transfer, Information & Promotion Staff | D29: SAI No. | F29: dtd.
A31: Stock No. | B31: Unit | C31: Item Description | D31: Qty. | E31: Unit Cost | F31: Total Cost
B32: =B9 -> kg | C32: GINNED COTTON FIBER Note: Including VAT and Delivery to ICYT Bldg., DOST-PTRI Bicutan, Taguig City | D32: =D9 -> 1500 | E32: =E9 -> 140 | F32: =F9 -> 210000
C35: -x-x-x-x-x-x-x-x-nothing follows-x-x-x-x-x-x-x-
C37: Charge to: GAA-TIPS: 2024 Uniform | F37: =F14 -> 210000
A38: Purpose: To be used for the project
C39: Requested by : | D39: Approved by :
A41: Signature
A42: Printed Name | C42: EVANGELINE FLOR P. MANALANG | D42: JULIUS L. LEAÑO JR.
A43: Designation | C43: Project Leader/ Head, OD-TIPS | D43: Director IV
A44: Date | C44: =C21 -> 45299

Sheet CHEMICALS 
A1: FAD-PPGSS Form No. 15
A2: Rev. 1/15-05-17
A3: PURCHASE REQUEST
A4: Philippine Textile Research Institute
A5: Division | B5: OFFICE OF THE DIRECTOR | D5: P.R. No. | F5: dtd.
A6: Section | B6: Technology Transfer, Information & Promotion Staff | D6: SAI No. | F6: dtd.
A8: Stock No. | B8: Unit | C8: Item Description | D8: Qty. | E8: Unit Cost | F8: Total Cost
C9: CHEMICALS
B10: cby | C10: Hydrogen Peroxide, Technical Grade 25 L/cby | D10: =Summary!F9 -> 9 | E10: =Summary!H9 -> 8000 | F10: =D10*E10 -> 72000
B11: cby | C11: =Summary!E10 -> Sodium Hydroxide, Liquid 48% 30 kg/cby | D11: =Summary!F10 -> 130 | E11: =Summary!H10 -> 3000 | F11: =D11*E11 -> 390000
B12: kg | C12: =Summary!E11 -> Sodium Metabisulfite, Technical Grade | D12: =Summary!F11 -> 180 | E12: =Summary!H11 -> 350 | F12: =D12*E12 -> 63000
B13: gal | C13: =Summary!E12 -> Anionic Detergent | D13: =Summary!F12 -> 50 | E13: =Summary!H12 -> 700 | F13: =D13*E13 -> 35000
B14: cby | C14: =Summary!E13 -> Acetic Acid, Technical Grade 20 kg/cby | D14: =Summary!F13 -> 38 | E14: =Summary!H13 -> 9500 | F14: =D14*E14 -> 361000
C15: -x-x-x-x-x-x-x-x-nothing follows-x-x-x-x-x-x-x-
C17: Charge to: GAA-TIPS: 2024 Uniform | F17: =sum(F10:G14) -> 921000
A18: Purpose: To be used for the project
C19: Requested by : | D19: Approved by :
A21: Signature
A22: Printed Name | C22: EVANGELINE FLOR P. MANALANG | D22: JULIUS L. LEAÑO JR.
A23: Designation | C23: Project Leader/ Head, OD-TIPS | D23: Director IV
A24: Date | C24: 45299
A27: FAD-PPGSS Form No. 15
A28: Rev. 1/15-05-17
A29: PURCHASE REQUEST
A30: Philippine Textile Research Institute
A31: Division | B31: OFFICE OF THE DIRECTOR | D31: P.R. No. | F31: dtd.
A32: Section | B32: Technology Transfer, Information & Promotion Staff | D32: SAI No. | F32: dtd.
A34: Stock No. | B34: Unit | C34: Item Description | D34: Qty. | E34: Unit Cost | F34: Total Cost
C35: CHEMICALS
B36: cby | C36: Hydrogen Peroxide, Technical Grade 25 L/cby | D36: =D10 -> 9 | E36: =E10 -> 8000 | F36: =D36*E36 -> 72000
B37: cby | C37: =C11 -> Sodium Hydroxide, Liquid 48% 30 kg/cby | D37: =D11 -> 130 | E37: =E11 -> 3000 | F37: =D37*E37 -> 390000
B38: kg | C38: =C12 -> Sodium Metabisulfite, Technical Grade | D38: =D12 -> 180 | E38: =E12 -> 350 | F38: =D38*E38 -> 63000
B39: gal | C39: =C13 -> Anionic Detergent | D39: =D13 -> 50 | E39: =E13 -> 700 | F39: =D39*E39 -> 35000
B40: cby | C40: =C14 -> Acetic Acid, Technical Grade 20 kg/cby | D40: =D14 -> 38 | E40: =E14 -> 9500 | F40: =D40*E40 -> 361000
C41: -x-x-x-x-x-x-x-x-nothing follows-x-x-x-x-x-x-x-
C43: Charge to: GAA-TIPS: 2024 Uniform | F43: =sum(F36:G40) -> 921000
A44: Purpose: To be used for the project
C45: Requested by : | D45: Approved by :
A47: Signature
A48: Printed Name | C48: EVANGELINE FLOR P. MANALANG | D48: JULIUS L. LEAÑO JR.
...

Sheet ENZYME FINISHING and DYEING of 
A1: FAD-PPGSS Form No. 15
A2: Rev. 1/15-05-17
A3: PURCHASE REQUEST
A4: Philippine Textile Research Institute
A5: Division | B5: OFFICE OF THE DIRECTOR | D5: P.R. No. | F5: dtd.
A6: Section | B6: Technology Transfer, Information & Promotion Staff | D6: SAI No. | F6: dtd.
A8: Stock No. | B8: Unit | C8: Item Description | D8: Qty. | E8: Unit Cost | F8: Total Cost
A9: 1 | B9: lot | C9: ENZYME FINISHING and DYEING of Powerloom woven fabrics | D9: 1 | E9: 30000 | F9: =E9*D9 -> 30000
C10: Weight: 40.7kgs
C11: Warp: 100% Polyester
C12: Warp: 70% cotton/ 30% Pineapple Leaf Fiber
C13: Shade: White, Beige, Yellow
C14: -x-x-x-x-x-x-x-x-nothing follows-x-x-x-x-x-x-x-
C15: Charge to: GAA-TIPS: 2024 Uniform | F15: =sum(F9) -> 30000
A16: Purpose: To be used for the project
C17: Requested by : | D17: Approved by :
A19: Signature
A20: Printed Name | C20: EVANGELINE FLOR P. MANALANG | D20: JULIUS L. LEAÑO JR.
A21: Designation | C21: Project Leader/ Head, OD-TIPS | D21: Director IV
A22: Date | C22: 45299
A25: FAD-PPGSS Form No. 15
A26: Rev. 1/15-05-17
A27: PURCHASE REQUEST
A28: Philippine Textile Research Institute
A29: Division | B29: OFFICE OF THE DIRECTOR | D29: P.R. No. | F29: dtd.
A30: Section | B30: Technology Transfer, Information & Promotion Staff | D30: SAI No. | F30: dtd.
A32: Stock No. | B32: Unit | C32: Item Description | D32: Qty. | E32: Unit Cost | F32: Total Cost
A33: 1 | B33: lot | C33: ENZYME FINISHING and DYEING of Powerloom woven fabrics | D33: 1 | E33: 30000 | F33: =F9 -> 30000
C34: Weight: 40.7kgs
C35: Warp: 100% Polyester
C36: Warp: 70% cotton/ 30% Pineapple Leaf Fiber
C37: Shade: White, Beige, Yellow
C38: -x-x-x-x-x-x-x-x-nothing follows-x-x-x-x-x-x-x-
C39: Charge to: GAA-TIPS: 2024 Uniform | F39: =sum(F33) -> 30000
A40: Purpose: To be used for the project
C41: Requested by : | D41: Approved by :
A43: Signature
A44: Printed Name | C44: EVANGELINE FLOR P. MANALANG | D44: JULIUS L. LEAÑO JR.
A45: Designation | C45: Project Leader/ Head, OD-TIPS | D45: Director IV
A46: Date | C46: 45299

Sheet COURIER FEE
A1: FAD-PPGSS Form No. 15
A2: Rev. 1/15-05-17
A3: PURCHASE REQUEST
A4: Philippine Textile Research Institute
A5: Division | B5: OFFICE OF THE DIRECTOR | D5: P.R. No. | F5: dtd.
A6: Section | B6: Technology Transfer, Information & Promotion Staff | D6: SAI No. | F6: dtd.
A8: Stock No. | B8: Unit | C8: Item Description | D8: Qty. | E8: Unit Cost | F8: Total Cost
A9: 1 | B9: lot | C9: Delivery of swatch fabrics from PTRI,General Santos Ave, Taguig City to Davao Fashion and Design Council Philippine Womens College of Davao University, Davao Del Sur | D9: 1 | E9: 215 | F9: =E9*D9 -> 215
C11: cash advance
C12: -x-x-x-x-x-x-x-x-nothing follows-x-x-x-x-x-x-x-
C13: Charge to: GAA-TIPS: 2024 Uniform | F13: =sum(F9) -> 215
A14: Purpose: To be used for the project
C15: Requested by : | D15: Approved by :
A17: Signature
A18: Printed Name | C18: EVANGELINE FLOR P. MANALANG | D18: JULIUS L. LEAÑO JR.
A19: Designation | C19: Project Leader/ Head, OD-TIPS | D19: Director IV
A20: Date | C20: 45300
A23: FAD-PPGSS Form No. 15
A24: Rev. 1/15-05-17
A25: PURCHASE REQUEST
A26: Philippine Textile Research Institute
A27: Division | B27: OFFICE OF THE DIRECTOR | D27: P.R. No. | F27: dtd.
A28: Section | B28: Technology Transfer, Information & Promotion Staff | D28: SAI No. | F28: dtd.
A30: Stock No. | B30: Unit | C30: Item Description | D30: Qty. | E30: Unit Cost | F30: Total Cost
A31: 1 | B31: lot | C31: Delivery of swatch fabrics from PTRI,General Santos Ave, Taguig City to Davao Fashion and Design Council Philippine Womens College of Davao University, Davao Del Sur | D31: 1 | E31: 215 | F31: =E31*D31 -> 215
C33: cash advance
C34: -x-x-x-x-x-x-x-x-nothing follows-x-x-x-x-x-x-x-
C35: Charge to: GAA-TIPS: 2024 Uniform | F35: =sum(F31) -> 215
A36: Purpose: To be used for the project
C37: Requested by : | D37: Approved by :
A39: Signature
A40: Printed Name | C40: EVANGELINE FLOR P. MANALANG | D40: JULIUS L. LEAÑO JR.
A41: Designation | C41: Project Leader/ Head, OD-TIPS | D41: Director IV
A42: Date | C42: =C20 -> 45300

Sheet DIESEL FUEL
A1: FAD-PPGSS Form No. 15
A2: Rev. 1/15-05-17
A3: PURCHASE REQUEST
A4: Philippine Textile Research Institute
A5: Division | B5: OFFICE OF THE DIRECTOR | D5: P.R. No. | F5: dtd.
A6: Section | B6: Technology Transfer, Information & Promotion Staff | D6: SAI No. | F6: dtd.
A8: Stock No. | B8: Unit | C8: Item Description | D8: Qty. | E8: Unit Cost | F8: Total Cost
A9: 1 | B9: drums | C9: DIESEL FUEL 210 liters / drum | D9: 30 | E9: 14000 | F9: =E9*D9 -> 420000
C12: -x-x-x-x-x-x-x-x-nothing follows-x-x-x-x-x-x-x-
C13: Charge to: GAA-TIPS: 2024 Uniform | F13: =sum(F9) -> 420000
A14: Purpose: To be used for the project
C15: Requested by : | D15: Approved by :
A17: Signature
A18: Printed Name | C18: EVANGELINE FLOR P. MANALANG | D18: JULIUS L. LEAÑO JR.
A19: Designation | C19: Project Leader/ Head, OD-TIPS | D19: Director IV
A20: Date | C20: 45306
A23: FAD-PPGSS Form No. 15
A24: Rev. 1/15-05-17
A25: PURCHASE REQUEST
A26: Philippine Textile Research Institute
A27: Division | B27: OFFICE OF THE DIRECTOR | D27: P.R. No. | F27: dtd.
A28: Section | B28: Technology Transfer, Information & Promotion Staff | D28: SAI No. | F28: dtd.
A30: Stock No. | B30: Unit | C30: Item Description | D30: Qty. | E30: Unit Cost | F30: Total Cost
A31: 1 | B31: =B9 -> drums | C31: =C9 -> DIESEL FUEL 210 liters / drum | D31: =D9 -> 30 | E31: =E9 -> 14000 | F31: =E31*D31 -> 420000
C34: -x-x-x-x-x-x-x-x-nothing follows-x-x-x-x-x-x-x-
C35: Charge to: GAA-TIPS: 2024 Uniform | F35: =sum(F31) -> 420000
A36: Purpose: To be used for the project
C37: Requested by : | D37: Approved by :
A39: Signature
A40: Printed Name | C40: EVANGELINE FLOR P. MANALANG | D40: JULIUS L. LEAÑO JR.
A41: Designation | C41: Project Leader/ Head, OD-TIPS | D41: Director IV
A42: Date | C42: =C20 -> 45306
